[3093111:MainThread](2024-04-25 05:11:11,701) INFO - qlib.Initialization - [config.py:416] - default_conf: client.
[3093111:MainThread](2024-04-25 05:11:11,704) INFO - qlib.Initialization - [__init__.py:74] - qlib successfully initialized based on client settings.
[3093111:MainThread](2024-04-25 05:11:11,704) INFO - qlib.Initialization - [__init__.py:76] - data_path={'__DEFAULT_FREQ': PosixPath('/home/zhonghao/.qlib/qlib_data/crowd_data')}
[3093111:MainThread](2024-04-25 05:11:11,705) ERROR - qlib.workflow - [utils.py:41] - An exception has been raised[FileNotFoundError: [Errno 2] No such file or directory: '/home/zhonghao/sjtu/qlib/examples/benchmarks/ADRNN/workflow_config_adrnn_Alpha360.yaml'].
  File "benchmark.py", line 370, in <module>
    fire.Fire(Benchmark)
  File "/home/zhonghao/miniconda3/envs/sjtu_qlib/lib/python3.8/site-packages/fire/core.py", line 143, in Fire
    component_trace = _Fire(component, args, parsed_flag_args, context, name)
  File "/home/zhonghao/miniconda3/envs/sjtu_qlib/lib/python3.8/site-packages/fire/core.py", line 477, in _Fire
    component, remaining_args = _CallAndUpdateTrace(
  File "/home/zhonghao/miniconda3/envs/sjtu_qlib/lib/python3.8/site-packages/fire/core.py", line 693, in _CallAndUpdateTrace
    component = fn(*varargs, **kwargs)
  File "benchmark.py", line 342, in run_exp
    rec = self.run_all()
  File "benchmark.py", line 253, in run_all
    task = self.basic_task()
  File "benchmark.py", line 139, in basic_task
    with conf_path.open("r") as f:
  File "/home/zhonghao/miniconda3/envs/sjtu_qlib/lib/python3.8/pathlib.py", line 1222, in open
    return io.open(self, mode, buffering, encoding, errors, newline,
  File "/home/zhonghao/miniconda3/envs/sjtu_qlib/lib/python3.8/pathlib.py", line 1078, in _opener
    return self._accessor.open(self, flags, mode)
FileNotFoundError: [Errno 2] No such file or directory: '/home/zhonghao/sjtu/qlib/examples/benchmarks/ADRNN/workflow_config_adrnn_Alpha360.yaml'
